Workbook

Sheet 1.总费用
A1: 宁德核电公司文档管理系统AI能力建设项目-工作量评估
A2: 序号 | B2: 工作项 | C2: 工作内容 | D2: 数量 | E2: 单位 | F2: 单价（元） | G2: 合计（元）
A3: 1 | B3: 需求分析 | C3: 对系统的需求变更进行需求分析及影响评估，制定需求实现方案。 | D3: ='2.工作量估算'!E46 -> 15.046437 | E3: 人月 | F3: 20000 | G3: =D3*F3 -> 300928.74
A4: 2 | B4: 系统设计 | C4: 系统设计 | D4: ='2.工作量估算'!F46 -> 11.285057 | E4: 人月 | F4: 20000 | G4: =D4*F4 -> 225701.15
A5: 3 | B5: 系统编码 | C5: 编码实现。 | D5: ='2.工作量估算'!G46 -> 30.093333 | E5: 人月 | F5: 20000 | G5: =D5*F5 -> 601866.67
A6: 4 | B6: 系统测试 | C6: 对修改结果进行测试验证以及发布前准备。 | D6: ='2.工作量估算'!H46 -> 11.285057 | E6: 人月 | F6: 20000 | G6: =D6*F6 -> 225701.15
A7: 5 | B7: 项目管理 | C7: 负责系统的投产发布环节和投产后的确认等工作，参与系统投产的填单及协调管理工作。 | D7: ='2.工作量估算'!I46 -> 7.5232184 | E7: 人月 | F7: 20000 | G7: =D7*F7 -> 150464.37
A8: 合计： | D8: =SUM(D3:D7) -> 75.233103 | E8: 人月 | G8: =SUM(G3:G7) -> 1504662.1
A9: 合并成本： | D9: 41.38 | E9: 人月 | F9: 20000 | G9: =D9*F9 -> 827600
A10: 利润率： | D10: =(G8-G9)/G8 -> 0.44997617

Sheet 2.工作量估算
A1: 序号 | B1: 模块 | C1: 功能 | D1: 功能内容 | E1: 需求人天 | F1: 设计人天 | G1: 编码人天 | H1: 测试人天 | I1: 管理人天 | J1: 合计 | K1: 真实编码人天 | L1: 备注
E2: 0.2 | F2: 0.15 | G2: 0.4 | H2: 0.15 | I2: 0.1 | J2: =SUM(E2:I2) -> 1
A3: =ROW()-2 -> 1 | B3: 知识智能体平台基础能力 | C3: 智能工作台 | D3: 提供应用入口、会话管理、应用检索、历史记录查看等能力，支持用户进入智能审核、文档问答、文件搜索等应用。 | E3: =$E$2*G3/$G$2 -> 9.09 | F3: =$F$2*G3/$G$2 -> 6.82 | G3: 18.18 | H3: =$H$2*G3/$G$2 -> 6.82 | I3: =$I$2*G3/$G$2 -> 4.54 | J3: =SUM(E3:I3) -> 45.45 | K3: 10
A4: =ROW()-2 -> 2 | C4: 应用管理 | D4: 支持创建、复制、调试、发布、下线智能体应用，支持版本管理和应用标签管理。 | E4: =$E$2*G4/$G$2 -> 7.28 | F4: =$F$2*G4/$G$2 -> 5.46 | G4: 14.55 | H4: =$H$2*G4/$G$2 -> 5.46 | I4: =$I$2*G4/$G$2 -> 3.64 | J4: =SUM(E4:I4) -> 36.39 | K4: 8
A5: =ROW()-2 -> 3 | C5: 工作流编排 | D5: 支持输入、输出、大模型、知识库检索、文档拆解、参数收集、条件分支、重排序、接口调用等节点编排。 | E5: =$E$2*G5/$G$2 -> 18.18 | F5: =$F$2*G5/$G$2 -> 13.64 | G5: 36.36 | H5: =$H$2*G5/$G$2 -> 13.64 | I5: =$I$2*G5/$G$2 -> 9.09 | J5: =SUM(E5:I5) -> 90.91 | K5: 20
A6: =ROW()-2 -> 4 | C6: 模型管理 | D6: 支持大语言模型、嵌入模型、重排序模型、多模态模型等统一接入、配置、启停和调用。 | E6: =$E$2*G6/$G$2 -> 7.28 | F6: =$F$2*G6/$G$2 -> 5.46 | G6: 14.55 | H6: =$H$2*G6/$G$2 -> 5.46 | I6: =$I$2*G6/$G$2 -> 3.64 | J6: =SUM(E6:I6) -> 36.39 | K6: 8
A7: =ROW()-2 -> 5 | C7: 知识库管理 | D7: 支持文档库、FAQ库的创建、上传、解析、检索和权限控制，支持审批规则、制度文件、模板说明等知识维护。 | E7: =$E$2*G7/$G$2 -> 13.64 | F7: =$F$2*G7/$G$2 -> 10.23 | G7: 27.27 | H7: =$H$2*G7/$G$2 -> 10.23 | I7: =$I$2*G7/$G$2 -> 6.82 | J7: =SUM(E7:I7) -> 68.19 | K7: 15
A8: =ROW()-2 -> 6 | C8: 文档解析 | D8: 支持Word、PDF、PPT、Excel、图片等常见格式解析，具备OCR识别、版面分析、段落拆解、表格抽取、字段抽取等能力。 | E8: =$E$2*G8/$G$2 -> 22.72 | F8: =$F$2*G8/$G$2 -> 17.04 | G8: 45.45 | H8: =$H$2*G8/$G$2 -> 17.04 | I8: =$I$2*G8/$G$2 -> 11.36 | J8: =SUM(E8:I8) -> 113.61 | K8: 25
A9: =ROW()-2 -> 7 | C9: 工具接口 | D9: 支持通过标准接口方式配置外部工具和业务服务，完成表单数据读取、附件解析、结果回写、日志记录等集成。 | E9: =$E$2*G9/$G$2 -> 9.09 | F9: =$F$2*G9/$G$2 -> 6.82 | G9: 18.18 | H9: =$H$2*G9/$G$2 -> 6.82 | I9: =$I$2*G9/$G$2 -> 4.54 | J9: =SUM(E9:I9) -> 45.45 | K9: 10
A10: =ROW()-2 -> 8 | C10: 权限与审计 | D10: 支持组织、角色、资源、数据权限配置，支持调用日志、操作日志、反馈日志和异常日志留痕。 | E10: =$E$2*G10/$G$2 -> 9.09 | F10: =$F$2*G10/$G$2 -> 6.82 | G10: 18.18 | H10: =$H$2*G10/$G$2 -> 6.82 | I10: =$I$2*G10/$G$2 -> 4.54 | J10: =SUM(E10:I10) -> 45.45 | K10: 10
A11: =ROW()-2 -> 9 | C11: 运营管理 | D11: 支持模板、提示词、规则、样本、反馈数据、效果评估指标的运营维护。 | E11: =$E$2*G11/$G$2 -> 7.28 | F11: =$F$2*G11/$G$2 -> 5.46 | G11: 14.55 | H11: =$H$2*G11/$G$2 -> 5.46 | I11: =$I$2*G11/$G$2 -> 3.64 | J11: =SUM(E11:I11) -> 36.39 | K11: 8
A12: =ROW()-2 -> 10 | B12: 智能审核应用能力 | C12: 审核模板配置 | D12: 按不同审批流程配置摘要模板、字段映射规则和审核关注点文案，模板明确需读取的字段信息，保证生成内容稳定可控。 | E12: =$E$2*G12/$G$2 -> 9.09 | F12: =$F$2*G12/$G$2 -> 6.82 | G12: 18.18 | H12: =$H$2*G12/$G$2 -> 6.82 | I12: =$I$2*G12/$G$2 -> 4.54 | J12: =SUM(E12:I12) -> 45.45 | K12: 10
A13: =ROW()-2 -> 11 | C13: 表单信息抽取 | D13: 审批人进入页面后，结合模板要求读取审批表单、文件/档案清单、附件内容及流程日志等对应信息。 | E13: =$E$2*G13/$G$2 -> 7.28 | F13: =$F$2*G13/$G$2 -> 5.46 | G13: 14.55 | H13: =$H$2*G13/$G$2 -> 5.46 | I13: =$I$2*G13/$G$2 -> 3.64 | J13: =SUM(E13:I13) -> 36.39 | K13: 8
A14: =ROW()-2 -> 12 | C14: 智能审核生成 | D14: 基于模板生成"一句话摘要+审核关注点+关键信息"，关键信息抽取准确率不低于85%。 | E14: =$E$2*G14/$G$2 -> 13.64 | F14: =$F$2*G14/$G$2 -> 10.23 | G14: 27.27 | H14: =$H$2*G14/$G$2 -> 10.23 | I14: =$I$2*G14/$G$2 -> 6.82 | J14: =SUM(E14:I14) -> 68.19 | K14: 15
A15: =ROW()-2 -> 13 | C15: 审核展示与人工确认 | D15: 智能审核结果在审批页面以独立面板或嵌入式区域展示，审批人可结合原始材料进行审批确认、修改、驳回或补充说明。 | E15: =$E$2*G15/$G$2 -> 10.91 | F15: =$F$2*G15/$G$2 -> 8.18 | G15: 21.82 | H15: =$H$2*G15/$G$2 -> 8.18 | I15: =$I$2*G15/$G$2 -> 5.46 | J15: =SUM(E15:I15) -> 54.55 | K15: 12
A16: =ROW()-2 -> 14 | C16: 反馈优化 | D16: 记录查看、采纳、修改、忽略、驳回等反馈数据，用于后续模板、规则、字段映射、提示词和模型效果优化。 | E16: =$E$2*G16/$G$2 -> 5.46 | F16: =$F$2*G16/$G$2 -> 4.09 | G16: 10.91 | H16: =$H$2*G16/$G$2 -> 4.09 | I16: =$I$2*G16/$G$2 -> 2.73 | J16: =SUM(E16:I16) -> 27.28 | K16: 6
A17: =ROW()-2 -> 15 | B17: 审批项目审核规则 | C17: 内部会议纪要审核 | D17: 校验与会人与基本信息及正文一致性、正文行动项（内容、责任人、完成期限）完整性、完成期限与会议时间冲突、与会人与分发设置一致性。 | E17: =$E$2*G17/$G$2 -> 5.46 | F17: =$F$2*G17/$G$2 -> 4.09 | G17: 10.91 | H17: =$H$2*G17/$G$2 -> 4.09 | I17: =$I$2*G17/$G$2 -> 2.73 | J17: =SUM(E17:I17) -> 27.28 | K17: 6
A18: =ROW()-2 -> 16 | C18: 外部会议纪要审核 | D18: 校验各节点处理人是否包含宁德公司之外人员，其余规则继承内部会议纪要。 | E18: =$E$2*G18/$G$2 -> 2.72 | F18: =$F$2*G18/$G$2 -> 2.04 | G18: 5.45 | H18: =$H$2*G18/$G$2 -> 2.04 | I18: =$I$2*G18/$G$2 -> 1.36 | J18: =SUM(E18:I18) -> 13.61 | K18: 3
A19: =ROW()-2 -> 17 | C19: 报告审核 | D19: 标题年度与基本信息年度一致性判断；标题含节日名称时检查正文一致性；正文章节号顺序检查；正文章节目录收录检查。 | E19: =$E$2*G19/$G$2 -> 7.28 | F19: =$F$2*G19/$G$2 -> 5.46 | G19: 14.55 | H19: =$H$2*G19/$G$2 -> 5.46 | I19: =$I$2*G19/$G$2 -> 3.64 | J19: =SUM(E19:I19) -> 36.39 | K19: 8
A20: =ROW()-2 -> 18 | C20: 发函审核 | D20: 回函编码中发文单位编码与发函编码中收文单位编码核对；正文附件名称与实际上传附件名称一致性判断；回函日期不能早于批准日期。 | E20: =$E$2*G20/$G$2 -> 4.54 | F20: =$F$2*G20/$G$2 -> 3.41 | G20: 9.09 | H20: =$H$2*G20/$G$2 -> 3.41 | I20: =$I$2*G20/$G$2 -> 2.27 | J20: =SUM(E20:I20) -> 22.72 | K20: 5
A21: =ROW()-2 -> 19 | C21: 事故规程审核 | D21: 直接上传PDF主件在线审批，用户上传PDF时自动提取编码、标题、页数、版本填充至基本信息对应字段（智能著录），审批后把审批人花签插入PDF。 | E21: =$E$2*G21/$G$2 -> 9.09 | F21: =$F$2*G21/$G$2 -> 6.82 | G21: 18.18 | H21: =$H$2*G21/$G$2 -> 6.82 | I21: =$I$2*G21/$G$2 -> 4.54 | J21: =SUM(E21:I21) -> 45.45 | K21: 10
A22: =ROW()-2 -> 20 | C22: 技术支持程序审核 | D22: 涉及相关设备、相关工具、相关备件、相关区域、反馈单等信息的读取与校验（本期暂无专项审核规则）。 | E22: =$E$2*G22/$G$2 -> 2.72 | F22: =$F$2*G22/$G$2 -> 2.04 | G22: 5.45 | H22: =$H$2*G22/$G$2 -> 2.04 | I22: =$I$2*G22/$G$2 -> 1.36 | J22: =SUM(E22:I22) -> 13.61 | K22: 3
A23: =ROW()-2 -> 21 | C23: 采购技术规范书审核 | D23: 编写环节目录完整性检查；正文是否包含所有目录对应内容；正文章节与最新模板对比，不一致提醒。 | E23: =$E$2*G23/$G$2 -> 5.46 | F23: =$F$2*G23/$G$2 -> 4.09 | G23: 10.91 | H23: =$H$2*G23/$G$2 -> 4.09 | I23: =$I$2*G23/$G$2 -> 2.73 | J23: =SUM(E23:I23) -> 27.28 | K23: 6
A24: =ROW()-2 -> 22 | C24: 系统功能授权申请审核 | D24: 附件必须上传保密承诺书检查；申请期限超过5年提醒。 | E24: =$E$2*G24/$G$2 -> 2.72 | F24: =$F$2*G24/$G$2 -> 2.04 | G24: 5.45 | H24: =$H$2*G24/$G$2 -> 2.04 | I24: =$I$2*G24/$G$2 -> 1.36 | J24: =SUM(E24:I24) -> 13.61 | K24: 3
A25: =ROW()-2 -> 23 | C25: 技术文件审核 | D25: 独立编码检查；电子文件命名与文件内容中名称一致性；临时文件生效章与制作章项目编号一致性；正式文件升版文件编码与上传电子文件编码一致性。 | E25: =$E$2*G25/$G$2 -> 4.54 | F25: =$F$2*G25/$G$2 -> 3.41 | G25: 9.09 | H25: =$H$2*G25/$G$2 -> 3.41 | I25: =$I$2*G25/$G$2 -> 2.27 | J25: =SUM(E25:I25) -> 22.72 | K25: 5
A26: =ROW()-2 -> 24 | B26: 文档智能服务能力 | C26: 智能著录 | D26: 上传或生成文档后自动识别关键字段并回填固定表单字段；支持OCR、版面分析、字段抽取、数据校验、人工确认/修正和著录入库。 | E26: =$E$2*G26/$G$2 -> 13.64 | F26: =$F$2*G26/$G$2 -> 10.23 | G26: 27.27 | H26: =$H$2*G26/$G$2 -> 10.23 | I26: =$I$2*G26/$G$2 -> 6.82 | J26: =SUM(E26:I26) -> 68.19 | K26: 15
A27: =ROW()-2 -> 25 | C27: 智能分发 | D27: 基于分发规则库和文档标题、关键词、摘要、事项描述等信息，辅助生成主送、抄送、协调员、分管领导等建议，支持权限与重复校验。 | E27: =$E$2*G27/$G$2 -> 9.09 | F27: =$F$2*G27/$G$2 -> 6.82 | G27: 18.18 | H27: =$H$2*G27/$G$2 -> 6.82 | I27: =$I$2*G27/$G$2 -> 4.54 | J27: =SUM(E27:I27) -> 45.45 | K27: 10
A28: =ROW()-2 -> 26 | C28: 智能推荐 | D28: 权限可控前提下，结合用户画像、行为日志、文档画像和反馈结果，推荐相关文档或知识内容，持续优化推荐策略。 | E28: =$E$2*G28/$G$2 -> 10.91 | F28: =$F$2*G28/$G$2 -> 8.18 | G28: 21.82 | H28: =$H$2*G28/$G$2 -> 8.18 | I28: =$I$2*G28/$G$2 -> 5.46 | J28: =SUM(E28:I28) -> 54.55 | K28: 12
A29: =ROW()-2 -> 27 | C29: 多模态智能体 | D29: 提供统一智能入口，支持流程发起指引、待办/待阅/已阅跳转、文件搜索等文本交互能力（本期以文字交互为主）。 | E29: =$E$2*G29/$G$2 -> 10.91 | F29: =$F$2*G29/$G$2 -> 8.18 | G29: 21.82 | H29: =$H$2*G29/$G$2 -> 8.18 | I29: =$I$2*G29/$G$2 -> 5.46 | J29: =SUM(E29:I29) -> 54.55 | K29: 12
A30: =ROW()-2 -> 28 | C30: 文件搜索 | D30: 支持按标题、发起人、部门、类型、正文片段等条件检索，调用语义检索并在文档管理系统页面展示结果，严格过滤无权限文档。 | E30: =$E$2*G30/$G$2 -> 9.09 | F30: =$F$2*G30/$G$2 -> 6.82 | G30: 18.18 | H30: =$H$2*G30/$G$2 -> 6.82 | I30: =$I$2*G30/$G$2 -> 4.54 | J30: =SUM(E30:I30) -> 45.45 | K30: 10
A31: =ROW()-2 -> 29 | B31: 智能代理流程 | C31: 代理需求识别 | D31: 审批人通过智能体入口输入代理审批自然语言指令，系统识别并抽取代理人、时间区间等关键信息，信息缺失时追问补全。 | E31: =$E$2*G31/$G$2 -> 7.28 | F31: =$F$2*G31/$G$2 -> 5.46 | G31: 14.55 | H31: =$H$2*G31/$G$2 -> 5.46 | I31: =$I$2*G31/$G$2 -> 3.64 | J31: =SUM(E31:I31) -> 36.39 | K31: 8
A32: =ROW()-2 -> 30 | C32: 代理人信息校验 | D32: 结合意图识别与实体抽取结果在人员主数据中检索代理人；姓名唯一进入配置确认，不唯一时展示姓名、部门、工号供确认。 | E32: =$E$2*G32/$G$2 -> 5.46 | F32: =$F$2*G32/$G$2 -> 4.09 | G32: 10.91 | H32: =$H$2*G32/$G$2 -> 4.09 | I32: =$I$2*G32/$G$2 -> 2.73 | J32: =SUM(E32:I32) -> 27.28 | K32: 6
A33: =ROW()-2 -> 31 | C33: 代理配置确认与执行 | D33: 展示并确认代理时间范围和代理范围后调用审批配置接口，在原审批人之外新增代理审批人，两者具备同等审批权限。 | E33: =$E$2*G33/$G$2 -> 5.46 | F33: =$F$2*G33/$G$2 -> 4.09 | G33: 10.91 | H33: =$H$2*G33/$G$2 -> 4.09 | I33: =$I$2*G33/$G$2 -> 2.73 | J33: =SUM(E33:I33) -> 27.28 | K33: 6
A34: =ROW()-2 -> 32 | C34: 日志留痕与边界控制 | D34: 记录配置发起人、代理人、代理范围、生效/失效时间、确认记录、接口调用结果和操作日志；代理时间非空、不得冲突、超期自动失效，异常情况阻止写入。 | E34: =$E$2*G34/$G$2 -> 5.46 | F34: =$F$2*G34/$G$2 -> 4.09 | G34: 10.91 | H34: =$H$2*G34/$G$2 -> 4.09 | I34: =$I$2*G34/$G$2 -> 2.73 | J34: =SUM(E34:I34) -> 27.28 | K34: 6
A35: =ROW()-2 -> 33 | B35: 系统集成与反馈优化 | C35: 表单数据读取接口 | D35: 读取审批页面申请表单、流程节点、申请人、申请部门、申请时间、审批状态等结构化信息。 | E35: =$E$2*G35/$G$2 -> 3.64 | F35: =$F$2*G35/$G$2 -> 2.73 | G35: 7.27 | H35: =$H$2*G35/$G$2 -> 2.73 | I35: =$I$2*G35/$G$2 -> 1.82 | J35: =SUM(E35:I35) -> 18.19 | K35: 4
A36: =ROW()-2 -> 34 | C36: 文件与档案清单读取接口 | D36: 读取文件列表、档案列表、相关文件、附件列表、文件名称、数量、类型、版本等信息。 | E36: =$E$2*G36/$G$2 -> 3.64 | F36: =$F$2*G36/$G$2 -> 2.73 | G36: 7.27 | H36: =$H$2*G36/$G$2 -> 2.73 | I36: =$I$2*G36/$G$2 -> 1.82 | J36: =SUM(E36:I36) -> 18.19 | K36: 4
A37: =ROW()-2 -> 35 | C37: 附件解析服务接口 | D37: 对Word、PDF、图片等附件调用正文解析、OCR识别、摘要生成和关键词抽取能力。 | E37: =$E$2*G37/$G$2 -> 4.54 | F37: =$F$2*G37/$G$2 -> 3.41 | G37: 9.09 | H37: =$H$2*G37/$G$2 -> 3.41 | I37: =$I$2*G37/$G$2 -> 2.27 | J37: =SUM(E37:I37) -> 22.72 | K37: 5
A38: =ROW()-2 -> 36 | C38: 智能审核结果回写接口 | D38: 将摘要、关注点、关键信息、生成时间、版本、来源字段等结果回写或展示到审批页面。 | E38: =$E$2*G38/$G$2 -> 3.64 | F38: =$F$2*G38/$G$2 -> 2.73 | G38: 7.27 | H38: =$H$2*G38/$G$2 -> 2.73 | I38: =$I$2*G38/$G$2 -> 1.82 | J38: =SUM(E38:I38) -> 18.19 | K38: 4
A39: =ROW()-2 -> 37 | C39: 权限校验集成 | D39: 所有搜索、推荐、读取、展示和回写均经过文档管理系统权限校验，确保无权限流程、页面和文档不展示。 | E39: =$E$2*G39/$G$2 -> 5.46 | F39: =$F$2*G39/$G$2 -> 4.09 | G39: 10.91 | H39: =$H$2*G39/$G$2 -> 4.09 | I39: =$I$2*G39/$G$2 -> 2.73 | J39: =SUM(E39:I39) -> 27.28 | K39: 6
A40: =ROW()-2 -> 38 | C40: 日志与反馈接口 | D40: 记录调用日志、展示日志、审批人反馈、代理配置确认记录、异常日志和效果评估数据，满足审计与持续优化要求。 | E40: =$E$2*G40/$G$2 -> 4.54 | F40: =$F$2*G40/$G$2 -> 3.41 | G40: 9.09 | H40: =$H$2*G40/$G$2 -> 3.41 | I40: =$I$2*G40/$G$2 -> 2.27 | J40: =SUM(E40:I40) -> 22.72 | K40: 5
...
